{"trial_id": "1", "hyperparameters": {"space": [{"class_name": "Int", "config": {"name": "layer_units", "default": null, "conditions": [], "min_value": 96, "max_value": 128, "step": 32, "sampling": "linear"}}], "values": {"layer_units": 128}}, "metrics": {"metrics": {}}, "score": null, "best_step": 0, "status": "FAILED", "message": "Traceback (most recent call last):\n  File \"c:\\Users\\Edgar\\AppData\\Local\\Programs\\Python\\Python310\\lib\\site-packages\\keras_tuner\\engine\\base_tuner.py\", line 270, in _try_run_and_update_trial\n    self._run_and_update_trial(trial, *fit_args, **fit_kwargs)\n  File \"c:\\Users\\Edgar\\AppData\\Local\\Programs\\Python\\Python310\\lib\\site-packages\\keras_tuner\\engine\\base_tuner.py\", line 235, in _run_and_update_trial\n    results = self.run_trial(trial, *fit_args, **fit_kwargs)\n  File \"c:\\Users\\Edgar\\AppData\\Local\\Programs\\Python\\Python310\\lib\\site-packages\\keras_tuner\\engine\\tuner.py\", line 287, in run_trial\n    obj_value = self._build_and_fit_model(trial, *args, **copied_kwargs)\n  File \"c:\\Users\\Edgar\\AppData\\Local\\Programs\\Python\\Python310\\lib\\site-packages\\keras_tuner\\engine\\tuner.py\", line 214, in _build_and_fit_model\n    results = self.hypermodel.fit(hp, model, *args, **kwargs)\n  File \"c:\\Users\\Edgar\\AppData\\Local\\Programs\\Python\\Python310\\lib\\site-packages\\keras_tuner\\engine\\hypermodel.py\", line 144, in fit\n    return model.fit(*args, **kwargs)\n  File \"c:\\Users\\Edgar\\AppData\\Local\\Programs\\Python\\Python310\\lib\\site-packages\\keras\\utils\\traceback_utils.py\", line 67, in error_handler\n    raise e.with_traceback(filtered_tb) from None\n  File \"C:\\Users\\Edgar\\AppData\\Local\\Temp\\__autograph_generated_filedwru9tlj.py\", line 15, in tf__train_function\n    retval_ = ag__.converted_call(ag__.ld(step_function), (ag__.ld(self), ag__.ld(iterator)), None, fscope)\nValueError: in user code:\n\n    File \"c:\\Users\\Edgar\\AppData\\Local\\Programs\\Python\\Python310\\lib\\site-packages\\keras\\engine\\training.py\", line 1051, in train_function  *\n        return step_function(self, iterator)\n    File \"c:\\Users\\Edgar\\AppData\\Local\\Programs\\Python\\Python310\\lib\\site-packages\\keras\\engine\\training.py\", line 1040, in step_function  **\n        outputs = model.distribute_strategy.run(run_step, args=(data,))\n    File \"c:\\Users\\Edgar\\AppData\\Local\\Programs\\Python\\Python310\\lib\\site-packages\\keras\\engine\\training.py\", line 1030, in run_step  **\n        outputs = model.train_step(data)\n    File \"c:\\Users\\Edgar\\AppData\\Local\\Programs\\Python\\Python310\\lib\\site-packages\\keras\\engine\\training.py\", line 890, in train_step\n        loss = self.compute_loss(x, y, y_pred, sample_weight)\n    File \"c:\\Users\\Edgar\\AppData\\Local\\Programs\\Python\\Python310\\lib\\site-packages\\keras\\engine\\training.py\", line 948, in compute_loss\n        return self.compiled_loss(\n    File \"c:\\Users\\Edgar\\AppData\\Local\\Programs\\Python\\Python310\\lib\\site-packages\\keras\\engine\\compile_utils.py\", line 201, in __call__\n        loss_value = loss_obj(y_t, y_p, sample_weight=sw)\n    File \"c:\\Users\\Edgar\\AppData\\Local\\Programs\\Python\\Python310\\lib\\site-packages\\keras\\losses.py\", line 139, in __call__\n        losses = call_fn(y_true, y_pred)\n    File \"c:\\Users\\Edgar\\AppData\\Local\\Programs\\Python\\Python310\\lib\\site-packages\\keras\\losses.py\", line 243, in call  **\n        return ag_fn(y_true, y_pred, **self._fn_kwargs)\n    File \"c:\\Users\\Edgar\\AppData\\Local\\Programs\\Python\\Python310\\lib\\site-packages\\keras\\losses.py\", line 1787, in categorical_crossentropy\n        return backend.categorical_crossentropy(\n    File \"c:\\Users\\Edgar\\AppData\\Local\\Programs\\Python\\Python310\\lib\\site-packages\\keras\\backend.py\", line 5119, in categorical_crossentropy\n        target.shape.assert_is_compatible_with(output.shape)\n\n    ValueError: Shapes (4, 2) and (4, 3) are incompatible\n\n"}